Namespace(data_path='data/really_final_constantless/really_final_constantless', debug=False, load_path=None, predict=False, release=False, save_path_prefix='models/really_final_constantless/model', seed=239, test_path='data/really_final_constantless/really_final_constantless.val.c2s')
2020-05-12 08:22:05.037330: I tensorflow/core/platform/cpu_feature_guard.cc:141] Your CPU supports instructions that this TensorFlow binary was not compiled to use: SSE4.1 SSE4.2 AVX AVX2 FMA
2020-05-12 08:22:05.057579: I tensorflow/core/common_runtime/process_util.cc:69] Creating new thread pool with default inter op setting: 2. Tune using inter_op_parallelism_threads for best performance.
Dictionaries loaded.
Loaded subtoken vocab. size: 3
Loaded target word vocab. size: 878
Loaded nodes vocab. size: 2672
Created model
Starting training
WARNING:tensorflow:From /home/danielben/anaconda3/envs/RE_project_1/lib/python3.6/site-packages/tensorflow/python/ops/sparse_ops.py:1165: sparse_to_dense (from tensorflow.python.ops.sparse_ops) is deprecated and will be removed in a future version.
Instructions for updating:
Create a `tf.sparse.SparseTensor` and use `tf.sparse.to_dense` instead.
Training batch size:			 8
Dataset path:				 data/really_final_constantless/really_final_constantless
Training file path:			 data/really_final_constantless/really_final_constantless.train.c2s
Validation path:			 data/really_final_constantless/really_final_constantless.val.c2s
Taking max contexts from each example:	 10
Random path sampling:			 False
Embedding size:				 128
Using BiLSTMs, each of size:		 128
Decoder size:				 320
Decoder layers:				 1
Max path lengths:			 798
Max subtokens in a token:		 1
Max target length:			 6
Embeddings dropout keep_prob:		 0.75
LSTM dropout keep_prob:			 0.5
============================================
Number of trainable params: 2454272
Initalized variables
Started reader...
Average loss at batch 100: 17.355155, 	throughput: 0 samples/sec
Finished 1 epochs
Done testing, epoch reached
Traceback (most recent call last):
  File "/home/danielben/anaconda3/envs/RE_project_1/lib/python3.6/site-packages/tensorflow/python/client/session.py", line 1334, in _do_call
    return fn(*args)
  File "/home/danielben/anaconda3/envs/RE_project_1/lib/python3.6/site-packages/tensorflow/python/client/session.py", line 1319, in _run_fn
    options, feed_dict, fetch_list, target_list, run_metadata)
  File "/home/danielben/anaconda3/envs/RE_project_1/lib/python3.6/site-packages/tensorflow/python/client/session.py", line 1407, in _call_tf_sessionrun
    run_metadata)
tensorflow.python.framework.errors_impl.OutOfRangeError: End of sequence
	 [[{{node IteratorGetNext}} = IteratorGetNext[output_shapes=[[?,10,798], [?,10], [?,10,1], [?,10], [?,10,1], [?,10,1], [?,10,1], [?,10], [?,10,1], [?,?], [?], [?], [?,10]], output_types=[DT_INT32, DT_INT32, DT_INT32, DT_INT32, DT_STRING, DT_STRING, DT_INT32, DT_INT32, DT_STRING, DT_INT32, DT_INT64, DT_STRING, DT_FLOAT], _device="/job:localhost/replica:0/task:0/device:CPU:0"](IteratorV2)]]

During handling of the above exception, another exception occurred:

Traceback (most recent call last):
  File "/home/danielben/automatic_functionality_detection/reda_project/code2seq/model.py", line 96, in train
    _, batch_loss = self.sess.run([optimizer, train_loss])
  File "/home/danielben/anaconda3/envs/RE_project_1/lib/python3.6/site-packages/tensorflow/python/client/session.py", line 929, in run
    run_metadata_ptr)
  File "/home/danielben/anaconda3/envs/RE_project_1/lib/python3.6/site-packages/tensorflow/python/client/session.py", line 1152, in _run
    feed_dict_tensor, options, run_metadata)
  File "/home/danielben/anaconda3/envs/RE_project_1/lib/python3.6/site-packages/tensorflow/python/client/session.py", line 1328, in _do_run
    run_metadata)
  File "/home/danielben/anaconda3/envs/RE_project_1/lib/python3.6/site-packages/tensorflow/python/client/session.py", line 1348, in _do_call
    raise type(e)(node_def, op, message)
tensorflow.python.framework.errors_impl.OutOfRangeError: End of sequence
	 [[node IteratorGetNext (defined at /home/danielben/automatic_functionality_detection/reda_project/code2seq/reader.py:192)  = IteratorGetNext[output_shapes=[[?,10,798], [?,10], [?,10,1], [?,10], [?,10,1], [?,10,1], [?,10,1], [?,10], [?,10,1], [?,?], [?], [?], [?,10]], output_types=[DT_INT32, DT_INT32, DT_INT32, DT_INT32, DT_STRING, DT_STRING, DT_INT32, DT_INT32, DT_STRING, DT_INT32, DT_INT64, DT_STRING, DT_FLOAT], _device="/job:localhost/replica:0/task:0/device:CPU:0"](IteratorV2)]]

Caused by op 'IteratorGetNext', defined at:
  File "code2seq.py", line 39, in <module>
    model.train()
  File "/home/danielben/automatic_functionality_detection/reda_project/code2seq/model.py", line 77, in train
    config=self.config)
  File "/home/danielben/automatic_functionality_detection/reda_project/code2seq/reader.py", line 43, in __init__
    self.output_tensors = self.compute_output()
  File "/home/danielben/automatic_functionality_detection/reda_project/code2seq/reader.py", line 192, in compute_output
    return self.iterator.get_next()
  File "/home/danielben/anaconda3/envs/RE_project_1/lib/python3.6/site-packages/tensorflow/python/data/ops/iterator_ops.py", line 421, in get_next
    name=name)), self._output_types,
  File "/home/danielben/anaconda3/envs/RE_project_1/lib/python3.6/site-packages/tensorflow/python/ops/gen_dataset_ops.py", line 2069, in iterator_get_next
    output_shapes=output_shapes, name=name)
  File "/home/danielben/anaconda3/envs/RE_project_1/lib/python3.6/site-packages/tensorflow/python/framework/op_def_library.py", line 787, in _apply_op_helper
    op_def=op_def)
  File "/home/danielben/anaconda3/envs/RE_project_1/lib/python3.6/site-packages/tensorflow/python/util/deprecation.py", line 488, in new_func
    return func(*args, **kwargs)
  File "/home/danielben/anaconda3/envs/RE_project_1/lib/python3.6/site-packages/tensorflow/python/framework/ops.py", line 3274, in create_op
    op_def=op_def)
  File "/home/danielben/anaconda3/envs/RE_project_1/lib/python3.6/site-packages/tensorflow/python/framework/ops.py", line 1770, in __init__
    self._traceback = tf_stack.extract_stack()

OutOfRangeError (see above for traceback): End of sequence
	 [[node IteratorGetNext (defined at /home/danielben/automatic_functionality_detection/reda_project/code2seq/reader.py:192)  = IteratorGetNext[output_shapes=[[?,10,798], [?,10], [?,10,1], [?,10], [?,10,1], [?,10,1], [?,10,1], [?,10], [?,10,1], [?,?], [?], [?], [?,10]], output_types=[DT_INT32, DT_INT32, DT_INT32, DT_INT32, DT_STRING, DT_STRING, DT_INT32, DT_INT32, DT_STRING, DT_INT32, DT_INT64, DT_STRING, DT_FLOAT], _device="/job:localhost/replica:0/task:0/device:CPU:0"](IteratorV2)]]


During handling of the above exception, another exception occurred:

Traceback (most recent call last):
  File "code2seq.py", line 39, in <module>
    model.train()
  File "/home/danielben/automatic_functionality_detection/reda_project/code2seq/model.py", line 108, in train
    results, precision, recall, f1, rouge = self.evaluate()
  File "/home/danielben/automatic_functionality_detection/reda_project/code2seq/model.py", line 228, in evaluate
    files_rouge = FilesRouge()
TypeError: __init__() missing 2 required positional arguments: 'hyp_path' and 'ref_path'
